Workbook

Sheet 7CC
A1: 7CC | B1: Time | C1: Monday | D1: Tuesday | E1: Wednesday | F1: Thursday | G1: Friday
B2: 07:55 08:00 | C2: Line up and lead in
A3: 1 | B3: 08:00 08:30 | C3: EMS | D3: Maths | E3: Eng | F3: Maths | G3: Eng
A4: 2 | B4: 08:30 09:00 | C4: EMS | D4: Maths | E4: eng | F4: Maths | G4: Eng
A5: 3 | B5: 09:00 09:30 | C5: Maths | D5: Eng | E5: Geog | F5: Afrik/Xhosa | G5: Afrik/Xhosa
A6: 4 | B6: 09:30 10:00 | C6: Maths | D6: Eng | E6: NST | F6: Afrik/Xhosa | G6: Afrik/Xhosa
A7: 5 | B7: 10:00 10:25 | C7: Break | D7: Break | E7: Break | F7: Break | G7: Break
A8: 6 | B8: 10:25 10:50 | C8: Assembly | D8: Geog | E8: Philosophy | F8: Sure/M | G8: NST
A9: 7 | B9: 10:50 11:15 | C9: Eng | D9: Geog | E9: Philosophy | F9: Music | G9: NST
A10: 8 | B10: 11:15 11: 40 | C10: Eng | D10: NST | E10: Comp | F10: Music | G10: Maths
A11: 9 | B11: 11:40 12:05 | C11: History | D11: NST | E11: Comp | F11: Eng | G11: Maths
A12: 10 | B12: 12:05 12:30 | C12: History | D12: History | E12: Chapel | F12: Eng | G12: Maths
A13: 11 | B13: 12:30 12:55 | C13: Break | D13: Break | E13: Break | F13: Break
A14: 12 | B14: 12:55 13:25 | C14: Afrik/Xhosa | D14: Choir | E14: Afrik/Xhosa | F14: NST
A15: 13 | B15: 13:25 13:55 | C15: Afrik/Xhosa | D15: Afrik/Xhosa | E15: Art | F15: PE
A16: 14 | B16: 13:55 14:25 | C16: Library | D16: Afrik/Xhosa | E16: Art | F16: PE

Sheet 7CW
A1: 7CW | B1: Time | C1: Monday | D1: Tuesday | E1: Wednesday | F1: Thursday | G1: Friday
B2: 07:55 08:00 | C2: Line up and lead in
A3: 1 | B3: 08:00 08:30 | C3: Eng | D3: NST | E3: EMS | F3: Maths | G3: NST
A4: 2 | B4: 08:30 09:00 | C4: Eng | D4: NST | E4: EMS | F4: Maths | G4: NST
A5: 3 | B5: 09:00 09:30 | C5: Geog | D5: Afrik/Xhosa | E5: Eng | F5: Eng | G5: Maths
A6: 4 | B6: 09:30 10:00 | C6: Geog | D6: Afrik/Xhosa | E6: Eng | F6: Eng | G6: Maths
A7: 5 | B7: 10:00 10:25 | C7: Break | D7: Break | E7: Break | F7: Break | G7: Break
A8: 6 | B8: 10:25 10:50 | C8: Assembly | D8: Eng | E8: Afrik/Xhosa | F8: Sure/M | G8: Eng
A9: 7 | B9: 10:50 11:15 | C9: Philosophy | D9: Eng | E9: Afrik/Xhosa | F9: Afrik/Xhosa | G9: Eng
A10: 8 | B10: 11:15 11: 40 | C10: Philosophy | D10: Afrik/Xhosa | E10: NST | F10: Afrik/Xhosa | G10: Geog
A11: 9 | B11: 11:40 12:05 | C11: Music | D11: Art | E11: NST | F11: Comp | G11: Afrik/Xhosa
A12: 10 | B12: 12:05 12:30 | C12: Music | D12: Art | E12: Chapel | F12: Comp | G12: Afrik/Xhosa
A13: 11 | B13: 12:30 12:55 | C13: Break | D13: Break | E13: Break | F13: Break
A14: 12 | B14: 12:55 13:25 | C14: Maths | D14: Choir | E14: History | F14: History
A15: 13 | B15: 13:25 13:55 | C15: Maths | D15: Maths | E15: History | F15: PE
A16: 14 | B16: 13:55 14:25 | C16: Maths | D16: Maths | E16: Library | F16: PE

Sheet 6RE
A1: 6RE | B1: Time | C1: Monday | D1: Tuesday | E1: Wednesday | F1: Thursday | G1: Friday
B2: 07:55 08:00 | C2: Line up and lead in
A3: 1 | B3: 08:00 08:30 | C3: Afrik/Xhosa | D3: Maths | E3: NST | F3: Eng | G3: Maths
A4: 2 | B4: 08:30 09:00 | C4: Afrik/Xhosa | D4: Maths | E4: NST | F4: Eng | G4: Maths
A5: 3 | B5: 09:00 09:30 | C5: Maths | D5: Eng | E5: Afrik/Xhosa | F5: Code/R | G5: Eng
A6: 4 | B6: 09:30 10:00 | C6: Maths | D6: Eng | E6: Afrik/Xhosa | F6: Code/R | G6: Eng
A7: 5 | B7: 10:00 10:25 | C7: Break | D7: Break | E7: Break | F7: Break | G7: Break
A8: 6 | B8: 10:25 10:50 | C8: Assembly | D8: Comp | E8: Eng | F8: Sure/M | G8: Afrik/Xhosa
A9: 7 | B9: 10:50 11:15 | C9: NST | D9: Comp | E9: Eng | F9: Maths | G9: Afrik/Xhosa
A10: 8 | B10: 11:15 11: 40 | C10: NST | D10: SS | E10: Philosophy | F10: Maths | G10: SS
A11: 9 | B11: 11:40 12:05 | C11: Eng | D11: Afrik/Xhosa | E11: Philosophy | F11: Music | G11: PE
A12: 10 | B12: 12:05 12:30 | C12: Eng | D12: Afrik/Xhosa | E12: Chapel | F12: Music | G12: PE
A13: 11 | B13: 12:30 12:55 | C13: Break | D13: Break | E13: Break | F13: Break
A14: 12 | B14: 12:55 13:25 | C14: NST | D14: Choir | E14: Consolidation | F14: Art
A15: 13 | B15: 13:25 13:55 | C15: Library | D15: SS | E15: SS | F15: Art
A16: 14 | B16: 13:55 14:25 | C16: Afrik/Xhosa | D16: SS | E16: SS | F16: Maths

Sheet 6CC
A1: 6NT | B1: Time | C1: Monday | D1: Tuesday | E1: Wednesday | F1: Thursday | G1: Friday
B2: 07:55 08:00 | C2: Line up and lead in
A3: 1 | B3: 08:00 08:30 | C3: NST | D3: Eng | E3: Eng | F3: Maths | G3: Eng
A4: 2 | B4: 08:30 09:00 | C4: NST | D4: Eng | E4: Eng | F4: Maths | G4: Eng
A5: 3 | B5: 09:00 09:30 | C5: Eng | D5: NST | E5: Code/R | F5: Maths | G5: Maths
A6: 4 | B6: 09:30 10:00 | C6: Eng | D6: NST | E6: Code/R | F6: SS | G6: Maths
A7: 5 | B7: 10:00 10:25 | C7: Break | D7: Break | E7: Break | F7: Break | G7: Break
A8: 6 | B8: 10:25 10:50 | C8: Assembly | D8: Library | E8: Comp | F8: Sure/M | G8: SS
A9: 7 | B9: 10:50 11:15 | C9: SS | D9: Maths | E9: Comp | F9: Eng | G9: SS
A10: 8 | B10: 11:15 11: 40 | C10: SS | D10: Maths | E10: Music | F10: Eng | G10: Afrik/Xhosa
A11: 9 | B11: 11:40 12:05 | C11: Afrik/Xhosa | D11: Philosophy | E11: Music | F11: Art | G11: PE
A12: 10 | B12: 12:05 12:30 | C12: Afrik/Xhosa | D12: Philosophy | E12: Chapel | F12: Art | G12: PE
A13: 11 | B13: 12:30 12:55 | C13: Break | D13: Break | E13: Break | F13: Break
A14: 12 | B14: 12:55 13:25 | C14: Maths | D14: Choir | E14: Afrik/Xhosa | F14: Afrik/Xhosa
A15: 13 | B15: 13:25 13:55 | C15: Maths | D15: Afrik/Xhosa | E15: Afrik/Xhosa | F15: Afrik/Xhosa
A16: 14 | B16: 13:55 14:25 | C16: SS | D16: Afrik/Xhosa | E16: NST | F16: Consolidation

Sheet 5SN
A1: 5SN | B1: Time | C1: Monday | D1: Tuesday | E1: Wednesday | F1: Thursday | G1: Friday
B2: 07:55 08:00 | C2: Line up and lead in
A3: 1 | B3: 08:00 08:30 | C3: Maths | D3: Music | E3: Maths | F3: Xhosa | G3: Art
A4: 2 | B4: 08:30 09:00 | C4: Maths | D4: Music | E4: Maths | F4: Xhosa | G4: Art
A5: 3 | B5: 09:00 09:30 | C5: Afrik | D5: Maths | E5: Eng | F5: Maths | G5: NS
A6: 4 | B6: 09:30 10:00 | C6: Afrik | D6: Maths | E6: Eng | F6: Maths | G6: NS
A7: 5 | B7: 10:00 10:25 | C7: Break | D7: Break | E7: Break | F7: Break | G7: Break
A8: 6 | B8: 10:25 10:50 | C8: Assembly | D8: PE | E8: NS | F8: Sure/M | G8: Eng
A9: 7 | B9: 10:50 11:15 | C9: Eng | D9: PE | E9: NS | F9: Eng | G9: Eng
A10: 8 | B10: 11:15 11: 40 | C10: Eng | D10: Eng | E10: Afrik | F10: Eng | G10: Afrik
A11: 9 | B11: 11:40 12:05 | C11: Xhosa | D11: Eng | E11: Afrik | F11: Afrik | G11: History
A12: 10 | B12: 12:05 12:30 | C12: Xhosa | D12: NS | E12: Chapel | F12: Afrik | G12: History
A13: 11 | B13: 12:30 12:55 | C13: Break | D13: Break | E13: Break | F13: Break
A14: 12 | B14: 12:55 13:25 | C14: Library | D14: Choir | E14: SS | F14: History
A15: 13 | B15: 13:25 13:55 | C15: Comp | D15: Xhosa | E15: SS | F15: Philosophy
A16: 14 | B16: 13:55 14:25 | C16: Comp | D16: Xhosa | E16: Maths | F16: Philosophy

Sheet 5ER
B1: Time | C1: Monday | D1: Tuesday | E1: Wednesday | F1: Thursday | G1: Friday
B2: 07:55 08:00 | C2: Line up and lead in
A3: 1 | B3: 08:00 08:30 | C3: Maths | D3: Maths | E3: Maths | F3: NS | G3: Music
A4: 2 | B4: 08:30 09:00 | C4: Maths | D4: Maths | E4: Maths | F4: NS | G4: Music
A5: 3 | B5: 09:00 09:30 | C5: Eng | D5: Art | E5: Philosophy | F5: Xhosa | G5: Eng
A6: 4 | B6: 09:30 10:00 | C6: Eng | D6: Art | E6: Philosophy | F6: Xhosa | G6: Eng
A7: 5 | B7: 10:00 10:25 | C7: Break | D7: Break | E7: Break | F7: Break | G7: Break
A8: 6 | B8: 10:25 10:50 | C8: Assembly | D8: PE | E8: Eng | F8: Sure/M | G8: History
A9: 7 | B9: 10:50 11:15 | C9: afrik | D9: PE | E9: Eng | F9: Eng | G9: SS
A10: 8 | B10: 11:15 11: 40 | C10: afrik | D10: Library | E10: Xhosa | F10: Eng | G10: SS
A11: 9 | B11: 11:40 12:05 | C11: NS | D11: afrik | E11: Xhosa | F11: afrik | G11: Comp
A12: 10 | B12: 12:05 12:30 | C12: NS | D12: afrik | E12: Chapel | F12: afrik | G12: Comp
A13: 11 | B13: 12:30 12:55 | C13: Break | D13: Break | E13: Break | F13: Break
A14: 12 | B14: 12:55 13:25 | C14: Xhosa | D14: Choir | E14: NS | F14: Maths
A15: 13 | B15: 13:25 13:55 | C15: Xhosa | D15: Eng | E15: History | F15: Maths
A16: 14 | B16: 13:55 14:25 | C16: afrik | D16: Eng | E16: History | F16: Maths

Sheet 4WP
A1: 4WP | B1: Time | C1: Monday | D1: Tuesday | E1: Wednesday | F1: Thursday | G1: Friday
B2: 07:55 08:00 | C2: Line up and lead in
A3: 1 | B3: 08:00 08:30 | C3: Maths | D3: Maths | E3: Maths | F3: Maths | G3: Eng
A4: 2 | B4: 08:30 09:00 | C4: Maths | D4: Maths | E4: Maths | F4: Maths | G4: Eng
A5: 3 | B5: 09:00 09:30 | C5: Eng | D5: SS | E5: Art | F5: NS | G5: Xhosa
A6: 4 | B6: 09:30 10:00 | C6: Eng | D6: SS | E6: Art | F6: NS | G6: Xhosa
A7: 5 | B7: 10:00 10:25 | C7: Break | D7: Break | E7: Break | F7: Break | G7: Break
A8: 6 | B8: 10:25 10:50 | C8: Assembly | D8: Xhosa | E8: Philosophy | F8: Sure/M | G8: Maths
A9: 7 | B9: 10:50 11:15 | C9: PE | D9: Xhosa | E9: Philosophy | F9: SS | G9: Music
A10: 8 | B10: 11:15 11: 40 | C10: PE | D10: Eng | E10: Eng | F10: SS | G10: Music
A11: 9 | B11: 11:40 12:05 | C11: Afrik | D11: Comp | E11: NS | F11: Eng | G11: Afrik
A12: 10 | B12: 12:05 12:30 | C12: Afrik | D12: Comp | E12: Chapel | F12: Eng | G12: Afrik
A13: 11 | B13: 12:30 12:55 | C13: Break | D13: Break | E13: Break | F13: Break
A14: 12 | B14: 12:55 13:25 | C14: Afrik | D14: Choir | E14: Library | F14: SS
A15: 13 | B15: 13:25 13:55 | C15: NS | D15: Afrik | E15: Eng | F15: Xhosa
A16: 14 | B16: 13:55 14:25 | C16: NS | D16: Afrik | E16: Eng | F16: Xhosa

Sheet IPLC
B1: Time | C1: Monday | D1: Tuesday | E1: Wednesday | F1: Thursday | G1: Friday
B2: 07:55 08:00 | C2: Line up and lead in
A3: 1 | B3: 08:00 08:30
A4: 2 | B4: 08:30 09:00
A5: 3 | B5: 09:00 09:30 | C5: Music | D5: Comp | F5: PE
A6: 4 | B6: 09:30 10:00 | C6: Music | D6: Comp | F6: PE
A7: 5 | B7: 10:00 10:25 | C7: Break | D7: Break | E7: Break | F7: Break | G7: Break
A8: 6 | B8: 10:25 10:50 | C8: Assembly | D8: Art | F8: Sure/M
A9: 7 | B9: 10:50 11:15 | D9: Art
A10: 8 | B10: 11:15 11: 40
A11: 9 | B11: 11:40 12:05
A12: 10 | B12: 12:05 12:30 | E12: Chapel | G12: Library
A13: 11 | B13: 12:30 12:55 | C13: Break | D13: Break | E13: Break | F13: Break
A14: 12 | B14: 12:55 13:25 | D14: Choir
A15: 13 | B15: 13:25 13:55
A16: 14 | B16: 13:55 14:25 | D16: Learning Centre Team Meeting

Sheet OLC
B1: Time | C1: Monday | D1: Tuesday | E1: Wednesday | F1: Thursday | G1: Friday
B2: 07:55 08:00 | C2: Line up and lead in
A3: 1 | B3: 08:00 08:30
A4: 2 | B4: 08:30 09:00
A5: 3 | B5: 09:00 09:30 | G5: Art
A6: 4 | B6: 09:30 10:00 | C6: 1st Break | D6: 1st Break | E6: 1st Break | F6: 1st Break | G6: Art
A7: 5 | B7: 10:00 10:25 | G7: Break
A8: 6 | B8: 10:25 10:50 | C8: Assembly | D8: Choir | F8: Sure
A9: 7 | B9: 10:50 11:15 | C9: Music | D9: Choir
A10: 8 | B10: 11:15 11: 40 | C10: Music
A11: 9 | B11: 11:40 12:05 | E11: Chapel | G11: Library
A12: 10 | B12: 12:05 12:30 | C12: 2nd Break | D12: 2nd Break | E12: 2nd Break | F12: 2nd Break
A13: 11 | B13: 12:30 12:55 | C13: PE | E13: Comp
A14: 12 | B14: 12:55 13:25 | C14: PE | E14: Comp
A15: 13 | B15: 13:25 13:55

Sheet 3SJ
B1: Time | C1: Monday | D1: Tuesday | E1: Wednesday | F1: Thursday | G1: Friday
B2: 07:55 08:00 | C2: Line up and lead in
A3: 1 | B3: 08:00 08:30
A4: 2 | B4: 08:30 09:00
A5: 3 | B5: 09:00 09:30
A6: 4 | B6: 09:30 10:00 | C6: 1st Break | D6: 1st Break | E6: 1st Break | F6: 1st Break
A7: 5 | B7: 10:00 10:25 | D7: Xhosa | E7: Art | G7: Break
A8: 6 | B8: 10:25 10:50 | C8: Assembly | D8: Choir | E8: Art | F8: Sure
A9: 7 | B9: 10:50 11:15 | D9: Choir
A10: 8 | B10: 11:15 11: 40 | F10: Xhosa
A11: 9 | B11: 11:40 12:05 | E11: Chapel | F11: Xhosa | G11: Music
A12: 10 | B12: 12:05 12:30 | C12: 2nd Break | D12: 2nd Break | E12: 2nd Break | F12: 2nd Break | G12: Music
A13: 11 | B13: 12:30 12:55 | C13: Comp | E13: Library | F13: PE
A14: 12 | B14: 12:55 13:25 | C14: Comp | F14: PE
A15: 13 | B15: 13:25 13:55

Sheet 3TA
B1: Time | C1: Monday | D1: Tuesday | E1: Wednesday | F1: Thursday | G1: Friday
B2: 07:55 08:00 | C2: Line up and lead in
A3: 1 | B3: 08:00 08:30
A4: 2 | B4: 08:30 09:00
A5: 3 | B5: 09:00 09:30 | G5: Music
A6: 4 | B6: 09:30 10:00 | C6: 1st Break | D6: 1st Break | E6: 1st Break | F6: 1st Break | G6: Music
A7: 5 | B7: 10:00 10:25 | F7: Xhosa | G7: Break
A8: 6 | B8: 10:25 10:50 | C8: Assembly | D8: Choir | F8: Sure | G8: Comp
A9: 7 | B9: 10:50 11:15 | D9: Choir | E9: Xhosa | G9: Comp
A10: 8 | B10: 11:15 11: 40 | E10: Xhosa
A11: 9 | B11: 11:40 12:05 | E11: Chapel
A12: 10 | B12: 12:05 12:30 | C12: 2nd Break | D12: 2nd Break | E12: 2nd Break | F12: 2nd Break
A13: 11 | B13: 12:30 12:55 | F13: PE
A14: 12 | B14: 12:55 13:25 | C14: Art | F14: PE
A15: 13 | B15: 13:25 13:55 | C15: Art | E15: Library

Sheet 2JD
A1: 2SJ | B1: Time | C1: Monday | D1: Tuesday | E1: Wednesday | F1: Thursday | G1: Friday
B2: 07:55 08:00 | C2: Line up and lead in
A3: 1 | B3: 08:00 08:30 | C3: Morning Ring/Show & Tell | D3: Morning Ring | E3: Morning Ring | F3: Morning Ring | G3: Morning Ring
A4: 2 | B4: 08:30 09:00 | C4: English | D4: Maths | E4: Handwriting/Cursive | F4: Maths | G4: Spelling CYP
A5: 3 | B5: 09:00 09:30 | C5: English | D5: Maths | E5: English | F5: Maths | G5: CYP
A6: 4 | B6: 09:30 10:00 | C6: 1st Break | D6: 1st Break | E6: 1st Break | F6: 1st Break | G6: CYP Maths
A7: 5 | B7: 10:00 10:25 | C7: English | D7: English | E7: Xhosa | F7: Sure | G7: Break
A8: 6 | B8: 10:25 10:50 | C8: Assembly | D8: Choir | E8: Xhosa | F8: English | G8: Afrikaans
A9: 7 | B9: 10:50 11:15 | C9: English | D9: Choir | E9: Maths | F9: Art | G9: Library
A10: 8 | B10: 11:15 11: 40 | C10: Comp | D10: Afrikaans | E10: Maths | F10: Art | G10: Afrikaans
A11: 9 | B11: 11:40 12:05 | C11: Comp | D11: Afrikaans | E11: Chapel | F11: English | G11: Reading
A12: 10 | B12: 12:05 12:30 | C12: 2nd Break | D12: 2nd Break | E12: 2nd Break | F12: 2nd Break | G12: Mindfulness
A13: 11 | B13: 12:30 12:55 | C13: Maths | D13: PE | E13: Music | F13: Life SkilPhilosophy
A14: 12 | B14: 12:55 13:30 | C14: Maths | D14: PE | E14: Music | F14: Life SkilPhilosophy
A15: 13 | B15: 13:25 13:40 | C15: Write down homework | D15: Write down homework | E15: Write down homework | F15: Write down homework

Sheet 1MJ
B1: Time | C1: Monday | D1: Tuesday | E1: Wednesday | F1: Thursday | G1: Friday
B2: 07:55 08:00 | C2: Line up and lead in
A3: 1 | B3: 08:00 08:30
A4: 2 | B4: 08:30 09:00
A5: 3 | B5: 09:00 09:30
A6: 4 | B6: 09:30 10:00 | C6: 1st Break | D6: 1st Break | E6: 1st Break | F6: 1st Break
A7: 5 | B7: 10:00 10:25 | E7: Music | F7: Comp | G7: Break
A8: 6 | B8: 10:25 10:50 | C8: Assembly | D8: Choir | E8: Music | F8: Sure
A9: 7 | B9: 10:50 11:15 | C9: Library | D9: Choir | G9: PE
A10: 8 | B10: 11:15 11: 40 | G10: PE
A11: 9 | B11: 11:40 12:05 | D11: Xhosa | E11: Chapel
A12: 10 | B12: 12:05 12:30 | C12: 2nd Break | D12: 2nd Break | E12: 2nd Break | F12: 2nd Break
A13: 11 | B13: 12:30 12:55 | D13: Art | F13: 3PE
A14: 12 | B14: 12:55 13:30 | D14: Art | F14: 3PE

Sheet 1AZ
B1: Time | C1: Monday | D1: Tuesday | E1: Wednesday | F1: Thursday | G1: Friday
B2: 07:55 08:00 | C2: Line up and lead in
A3: 1 | B3: 08:00 08:30
A4: 2 | B4: 08:30 09:00
A5: 3 | B5: 09:00 09:30
A6: 4 | B6: 09:30 10:00 | C6: 1st Break | D6: 1st Break | E6: 1st Break | F6: 1st Break
A7: 5 | B7: 10:00 10:25 | G7: Break
A8: 6 | B8: 10:25 10:50 | C8: Assembly | D8: Choir | F8: Sure
A9: 7 | B9: 10:50 11:15 | C9: Art | D9: Choir | F9: Comp | G9: PE
A10: 8 | B10: 11:15 11: 40 | C10: Art | D10: Xhosa | G10: PE
A11: 9 | B11: 11:40 12:05 | C11: Library | E11: Chapel
A12: 10 | B12: 12:05 12:30 | C12: 2nd Break | D12: 2nd Break | E12: 2nd Break | F12: 2nd Break
A13: 11 | B13: 12:30 12:55 | D13: Music | F13: 3PE
A14: 12 | B14: 12:55 13:30 | D14: Music | F14: 3PE

Sheet RLW
A1: RJB | B1: Time | C1: Monday | D1: Tuesday | E1: Wednesday | F1: Thursday | G1: Friday
B2: 07:55 08:00 | C2: Line up and lead in
A3: 1 | B3: 08:00 08:30
A4: 2 | B4: 08:30 09:00
A5: 3 | B5: 09:00 09:30
A6: 4 | B6: 09:30 10:00
A7: 5 | B7: 10:00 10:25 | C7: 1st Break | D7: 1st Break | E7: 1st Break | F7: 1st Break | G7: Break
A8: 6 | B8: 10:25 10:50 | C8: Comp | F8: PE
A9: 7 | B9: 10:50 11:15 | D9: Library | F9: PE
A10: 8 | B10: 11:15 11: 40 | D10: Music | E10: Art
A11: 9 | B11: 11:40 12:05 | C11: Xhosa | E11: Art
A12: 10 | B12: 12:05 12:30

Sheet CC
A1: CC | B1: Time | C1: Monday | D1: Tuesday | E1: Wednesday | F1: Thursday | G1: Friday
B2: 07:55 08:00 | C2: Register Class
A3: 1 | B3: 08:00 08:30 | C3: Eng 7CW | E3: Eng 7CC | G3: Eng 7CC
A4: 2 | B4: 08:30 09:00 | C4: Eng 7CW | E4: Eng 7CC | G4: Eng 7CC
A5: 3 | B5: 09:00 09:30 | C5: Eng 5ER | D5: Eng 7CC | E5: Eng 7CW | F5: Eng 7CW | G5: Eng 5ER
A6: 4 | B6: 09:30 10:00 | C6: Eng 5ER | D6: Eng 7CC | E6: Eng 7CW | F6: Eng 7CW | G6: Eng 5ER
A7: 5 | B7: 10:00 10:25 | C7: Break 7CC | D7: Break 7CC | E7: Break 7CC | F7: Break 7CC | G7: Break 7CC
A8: 6 | B8: 10:25 10:50 | C8: Assembly 7CC | D8: Eng 7CW | E8: Eng 5ER | F8: Sure/m 7CC | G8: Eng 7CW
A9: 7 | B9: 10:50 11:15 | C9: Eng 7CC | D9: Eng 7CW | E9: Eng 5ER | F9: Eng 5ER | G9: Eng 7CW
A10: 8 | B10: 11:15 11: 40 | C10: Eng 7CC | F10: Eng 5ER
A11: 9 | B11: 11:40 12:05 | C11: History 7CC | F11: Eng 7CC
A12: 10 | B12: 12:05 12:30 | C12: History 7CC | D12: History 7CC | E12: Chapel 7CC | F12: Eng 7CC
A13: 11 | B13: 12:30 12:55 | C13: Break 7CC | D13: Break 7CC | E13: Break 7CC | F13: Break 7CC
A14: 12 | B14: 12:55 13:25 | D14: Choir 7CC | E14: History 7CW | F14: History 7CW
A15: 13 | B15: 13:25 13:55 | D15: Eng 5ER | E15: History 7CW | F15: Pe 7CC
A16: 14 | B16: 13:55 14:25 | D16: Eng 5ER | F16: Pe 7CC

Sheet CW
A1: CW | B1: Time | C1: Monday | D1: Tuesday | E1: Wednesday | F1: Thursday | G1: Friday
B2: 07:55 08:00 | C2: Register Class
A3: 1 | B3: 08:00 08:30 | C3: Nst 6CC | D3: Nst 7CW | E3: Nst 6RE | F3: Ns 5ER | G3: Nst 7CW
A4: 2 | B4: 08:30 09:00 | C4: Nst 6CC | D4: Nst 7CW | E4: Nst 6RE | F4: Ns 5ER | G4: Nst 7CW
A5: 3 | B5: 09:00 09:30 | C5: Geog 7CW | D5: Nst 6CC | E5: Geog 7CC | G5: Ns 5SN
A6: 4 | B6: 09:30 10:00 | C6: Geog 7CW | D6: Nst 6CC | E6: Nst 7CC | G6: Ns 5SN
A7: 5 | B7: 10:00 10:25 | C7: Break 7CC | D7: Break 7CC | E7: Break 7CC | F7: Break 7CC | G7: Break 7CC
A8: 6 | B8: 10:25 10:50 | C8: Assembly 7CC | D8: Geog 7CC | E8: Ns 5SN | F8: Sure/m 7CC | G8: Nst 7CC
A9: 7 | B9: 10:50 11:15 | C9: Nst 6RE | D9: Geog 7CC | E9: Ns 5SN | G9: Nst 7CC
A10: 8 | B10: 11:15 11: 40 | C10: Nst 6RE | D10: Nst 7CC | E10: Nst 7CW | G10: Geog 7CW
A11: 9 | B11: 11:40 12:05 | C11: Ns 5ER | D11: Nst 7CC | E11: Nst 7CW
A12: 10 | B12: 12:05 12:30 | C12: Ns 5ER | D12: Ns 5SN | E12: Chapel 7CC
A13: 11 | B13: 12:30 12:55 | C13: Break 7CC | D13: Break 7CC | E13: Break 7CC | F13: Break 7CC
A14: 12 | B14: 12:55 13:25 | C14: Nst 6RE | D14: Choir 7CC | E14: Ns 5ER | F14: Nst 7CC
A15: 13 | B15: 13:25 13:55 | F15: Pe 7CC
A16: 14 | B16: 13:55 14:25 | E16: Nst 6CC | F16: Pe 7CC

Sheet RE
A1: RE | B1: Time | C1: Monday | D1: Tuesday | E1: Wednesday | F1: Thursday | G1: Friday
B2: 07:55 08:00 | C2: Register Class
A3: 1 | B3: 08:00 08:30 | D3: Eng 6CC | E3: Eng 6CC | F3: Eng 6RE | G3: Eng 6CC
A4: 2 | B4: 08:30 09:00 | D4: Eng 6CC | E4: Eng 6CC | F4: Eng 6RE | G4: Eng 6CC
A5: 3 | B5: 09:00 09:30 | C5: Eng 6CC | D5: Eng 6RE | G5: Eng 6RE
A6: 4 | B6: 09:30 10:00 | C6: Eng 6CC | D6: Eng 6RE | F6: Ss 6CC | G6: Eng 6RE
A7: 5 | B7: 10:00 10:25 | C7: Break 7CC | D7: Break 7CC | E7: Break 7CC | F7: Break 7CC | G7: Break 7CC
A8: 6 | B8: 10:25 10:50 | C8: Assembly 6RE | E8: Eng 6RE | F8: Sure/m 6RE | G8: Ss 6CC
A9: 7 | B9: 10:50 11:15 | C9: Ss 6CC | E9: Eng 6RE | F9: Eng 6CC | G9: Ss 6CC
A10: 8 | B10: 11:15 11: 40 | C10: Ss 6CC | D10: Ss 6RE | E10: Philosophy 6RE | F10: Eng 6CC | G10: Ss 6RE
A11: 9 | B11: 11:40 12:05 | C11: Eng 6RE | D11: Philosophy 6CC | E11: Philosophy 6RE | G11: Pe 6RE
A12: 10 | B12: 12:05 12:30 | C12: Eng 6RE | D12: Philosophy 6CC | E12: Chapel 6RE | G12: Pe 6RE
A13: 11 | B13: 12:30 12:55 | C13: Break 7CC | D13: Break 7CC | E13: Break 7CC | F13: Break 7CC
A14: 12 | B14: 12:55 13:25 | D14: Choir 6RE | E14: Consolidation 6RE
A15: 13 | B15: 13:25 13:55 | D15: Ss 6RE | E15: Ss 6RE
A16: 14 | B16: 13:55 14:25 | C16: Ss 6CC | D16: Ss 6RE | E16: Ss 6RE

Sheet CC6
A1: NT6 | B1: Time | C1: Monday | D1: Tuesday | E1: Wednesday | F1: Thursday | G1: Friday
B2: 07:55 08:00 | C2: Register Class
A3: 1 | B3: 08:00 08:30 | C3: Afrik/xhosa 6RE | D3: Maths 6RE | F3: Maths 6CC | G3: Maths 6RE
A4: 2 | B4: 08:30 09:00 | C4: Afrik/xhosa 6RE | D4: Maths 6RE | F4: Maths 6CC | G4: Maths 6RE
A5: 3 | B5: 09:00 09:30 | C5: Maths 6RE | E5: Afrik/xhosa 6RE | F5: Maths 6CC | G5: Maths 6CC
A6: 4 | B6: 09:30 10:00 | C6: Maths 6RE | E6: Afrik/xhosa 6RE | G6: Maths 6CC
A7: 5 | B7: 10:00 10:25 | C7: Break 7CC | D7: Break 7CC | E7: Break 7CC | F7: Break 7CC | G7: Break 7CC
A8: 6 | B8: 10:25 10:50 | C8: Assembly 6CC | F8: Sure/m 6CC | G8: Afrik/xhosa 6RE
A9: 7 | B9: 10:50 11:15 | D9: Maths 6CC | F9: Maths 6RE | G9: Afrik/xhosa 6RE
A10: 8 | B10: 11:15 11: 40 | D10: Maths 6CC | F10: Maths 6RE | G10: Afrik/xhosa 6CC
A11: 9 | B11: 11:40 12:05 | C11: Afrik/xhosa 6CC | D11: Afrik/xhosa 6RE | G11: Pe 6CC
A12: 10 | B12: 12:05 12:30 | C12: Afrik/xhosa 6CC | D12: Afrik/xhosa 6RE | E12: Chapel 6CC | G12: Pe 6CC
A13: 11 | B13: 12:30 12:55 | C13: Break 7CC | D13: Break 7CC | E13: Break 7CC | F13: Break 7CC
A14: 12 | B14: 12:55 13:25 | C14: Maths 6CC | D14: Choir 6CC | E14: Afrik/xhosa 6CC | F14: Afrik/xhosa 6CC
A15: 13 | B15: 13:25 13:55 | C15: Maths 6CC | D15: Afrik/xhosa 6CC | E15: Afrik/xhosa 6CC | F15: Afrik/xhosa 6CC
A16: 14 | B16: 13:55 14:25 | C16: Afrik/xhosa 6RE | D16: Afrik/xhosa 6CC | F16: Maths 6RE

Sheet SN
A1: SN | B1: Time | C1: Monday | D1: Tuesday | E1: Wednesday | F1: Thursday | G1: Friday
B2: 07:55 08:00 | C2: Register Class
A3: 1 | B3: 08:00 08:30 | C3: Maths 5SN | E3: Maths 5SN | F3: Maths 7CW
A4: 2 | B4: 08:30 09:00 | C4: Maths 5SN | E4: Maths 5SN | F4: Maths 7CW
A5: 3 | B5: 09:00 09:30 | C5: Afrik 5SN | D5: Maths 5SN | E5: Eng 5SN | F5: Maths 5SN | G5: Maths 7CW
A6: 4 | B6: 09:30 10:00 | C6: Afrik 5SN | D6: Maths 5SN | E6: Eng 5SN | F6: Maths 5SN | G6: Maths 7CW
A7: 5 | B7: 10:00 10:25 | C7: Break 7CC | D7: Break 7CC | E7: Break 7CC | F7: Break 7CC | G7: Break 7CC
A8: 6 | B8: 10:25 10:50 | C8: Assembly 5SN | D8: Pe 5SN | F8: Sure/m 5SN | G8: Eng 5SN
A9: 7 | B9: 10:50 11:15 | C9: Eng 5SN | D9: Pe 5SN | F9: Eng 5SN | G9: Eng 5SN
A10: 8 | B10: 11:15 11: 40 | C10: Eng 5SN | D10: Eng 5SN | E10: Afrik 5SN | F10: Eng 5SN | G10: Afrik 5SN
A11: 9 | B11: 11:40 12:05 | D11: Eng 5SN | E11: Afrik 5SN | F11: Afrik 5SN
A12: 10 | B12: 12:05 12:30 | E12: Chapel 5SN | F12: Afrik 5SN
A13: 11 | B13: 12:30 12:55 | C13: Break 7CC | D13: Break 7CC | E13: Break 7CC | F13: Break 7CC
A14: 12 | B14: 12:55 13:25 | C14: Maths 7CW | D14: Choir 5SN | E14: Ss 5SN
A15: 13 | B15: 13:25 13:55 | C15: Maths 7CW | D15: Maths 7CW | E15: Ss 5SN
A16: 14 | B16: 13:55 14:25 | C16: Maths 7CW | D16: Maths 7CW | E16: Maths 5SN

Sheet ER
A1: ER | B1: Time | C1: Monday | D1: Tuesday | E1: Wednesday | F1: Thursday | G1: Friday
B2: 07:55 08:00 | C2: Register Class
A3: 1 | B3: 08:00 08:30 | C3: Maths 5ER | D3: Maths 5ER | E3: Maths 5ER
A4: 2 | B4: 08:30 09:00 | C4: Maths 5ER | D4: Maths 5ER | E4: Maths 5ER
A5: 3 | B5: 09:00 09:30 | D5: Afrik 7CW | F5: Afrik 7CC | G5: Afrik 7CC
A6: 4 | B6: 09:30 10:00 | D6: Afrik 7CW | F6: Afrik 7CC | G6: Afrik 7CC
A7: 5 | B7: 10:00 10:25 | C7: Break 7CC | D7: Break 7CC | E7: Break 7CC | F7: Break 7CC | G7: Break 7CC
A8: 6 | B8: 10:25 10:50 | C8: Assembly 5ER | D8: Pe 5ER | E8: Afrik 7CW | F8: Sure/m 5ER
A9: 7 | B9: 10:50 11:15 | C9: Afrik 5ER | D9: Pe 5ER | E9: Afrik 7CW | F9: Afrik 7CW | G9: Ss 5ER
A10: 8 | B10: 11:15 11: 40 | C10: Afrik 5ER | D10: Afrik 7CW | F10: Afrik 7CW | G10: Ss 5ER
A11: 9 | B11: 11:40 12:05 | D11: Afrik 5ER | F11: Afrik 5ER | G11: Afrik 7CW
A12: 10 | B12: 12:05 12:30 | D12: Afrik 5ER | E12: Chapel 5ER | F12: Afrik 5ER | G12: Afrik 7CW
A13: 11 | B13: 12:30 12:55 | C13: Break 7CC | D13: Break 7CC | E13: Break 7CC | F13: Break 7CC
A14: 12 | B14: 12:55 13:25 | C14: Afrik 7CC | D14: Choir 5ER | E14: Afrik 7CC | F14: Maths 5ER
A15: 13 | B15: 13:25 13:55 | C15: Afrik 7CC | D15: Afrik 7CC | F15: Maths 5ER
A16: 14 | B16: 13:55 14:25 | C16: Afrik 5ER | D16: Afrik 7CC | F16: Maths 5ER

Sheet WP
A1: WP | B1: Time | C1: Monday | D1: Tuesday | E1: Wednesday | F1: Thursday | G1: Friday
B2: 07:55 08:00 | C2: Register Class
A3: 1 | B3: 08:00 08:30 | C3: Maths 4WP | D3: Maths 4WP | E3: Maths 4WP | F3: Maths 4WP | G3: Eng 4WP
A4: 2 | B4: 08:30 09:00 | C4: Maths 4WP | D4: Maths 4WP | E4: Maths 4WP | F4: Maths 4WP | G4: Eng 4WP
A5: 3 | B5: 09:00 09:30 | C5: Eng 4WP | D5: Ss 4WP | F5: Ns 4WP
A6: 4 | B6: 09:30 10:00 | C6: Eng 4WP | D6: Ss 4WP | F6: Ns 4WP
A7: 5 | B7: 10:00 10:25 | C7: Break 7CC | D7: Break 7CC | E7: Break 7CC | F7: Break 7CC | G7: Break 7CC
A8: 6 | B8: 10:25 10:50 | C8: Assembly 4WP | E8: Philosophy 4WP | F8: Sure/m 4WP | G8: Maths 4WP
A9: 7 | B9: 10:50 11:15 | C9: Pe 4WP | E9: Philosophy 4WP | F9: Ss 4WP
A10: 8 | B10: 11:15 11: 40 | C10: Pe 4WP | D10: Eng 4WP | E10: Eng 4WP | F10: Ss 4WP
A11: 9 | B11: 11:40 12:05 | C11: Afrik 4WP | E11: Ns 4WP | F11: Eng 4WP | G11: Afrik 4WP
A12: 10 | B12: 12:05 12:30 | C12: Afrik 4WP | E12: Chapel 4WP | F12: Eng 4WP | G12: Afrik 4WP
A13: 11 | B13: 12:30 12:55 | C13: Break 7CC | D13: Break 7CC | E13: Break 7CC | F13: Break 7CC
A14: 12 | B14: 12:55 13:25 | C14: Afrik 4WP | D14: Choir 4WP | F14: Ss 4WP
A15: 13 | B15: 13:25 13:55 | C15: Ns 4WP | D15: Afrik 4WP | E15: Eng 4WP
A16: 14 | B16: 13:55 14:25 | C16: Ns 4WP | D16: Afrik 4WP | E16: Eng 4WP

Sheet TD
A1: TD | B1: Time | C1: Monday | D1: Tuesday | E1: Wednesday | F1: Thursday | G1: Friday
B2: 07:55 08:00 | C2: Register Class
A3: 1 | B3: 08:00 08:30 | C3: Xhosa 6RE | F3: Xhosa 5SN
A4: 2 | B4: 08:30 09:00 | C4: Xhosa 6RE | F4: Xhosa 5SN
A5: 3 | B5: 09:00 09:30 | D5: Xhosa 7CW | E5: Xhosa 6RE | F5: Xhosa 5ER | G5: Xhosa 4WP
A6: 4 | B6: 09:30 10:00 | D6: Xhosa 7CW | E6: Xhosa 6RE | F6: Xhosa 5ER | G6: Xhosa 4WP
A7: 5 | B7: 10:00 10:25
A8: 6 | B8: 10:25 10:50 | D8: Xhosa 4WP | E8: Xhosa 7CW | G8: Xhosa 6RE
A9: 7 | B9: 10:50 11:15 | D9: Xhosa 4WP | E9: Xhosa 7CW | F9: Xhosa 7CW | G9: Xhosa 6RE
A10: 8 | B10: 11:15 11: 40 | D10: Xhosa 7CW | E10: Xhosa 5ER | F10: Xhosa 7CW
A11: 9 | B11: 11:40 12:05 | C11: Xhosa 5SN | D11: Xhosa 6RE | E11: Xhosa 5ER | G11: Xhosa 7CW
A12: 10 | B12: 12:05 12:30 | C12: Xhosa 5SN | D12: Xhosa 6RE | G12: Xhosa 7CW
A13: 11 | B13: 12:30 12:55
A14: 12 | B14: 12:55 13:25 | C14: Xhosa 5ER
A15: 13 | B15: 13:25 13:55 | C15: Xhosa 5ER | D15: Xhosa 5SN | F15: Xhosa 4WP
A16: 14 | B16: 13:55 14:25 | C16: Xhosa 6RE | D16: Xhosa 5SN | F16: Xhosa 4WP

Sheet ZM
A1: ZM | B1: Time | C1: Monday | D1: Tuesday | E1: Wednesday | F1: Thursday | G1: Friday
B2: 07:55 08:00 | C2: Register Class
A3: 1 | B3: 08:00 08:30
A4: 2 | B4: 08:30 09:00
A5: 3 | B5: 09:00 09:30
A6: 4 | B6: 09:30 10:00
A7: 5 | B7: 10:00 10:25 | D7: Xhosa 3SJ | E7: Xhosa 2JD | F7: Xhosa 3TA
A8: 6 | B8: 10:25 10:50 | E8: Xhosa 2JD
A9: 7 | B9: 10:50 11:15 | E9: Xhosa 3TA
A10: 8 | B10: 11:15 11: 40 | D10: Xhosa 1AZ | E10: Xhosa 3TA | F10: Xhosa 3SJ
A11: 9 | B11: 11:40 12:05 | C11: Xhosa RLW | D11: Xhosa 1MJ | F11: Xhosa 3SJ
A12: 10 | B12: 12:05 12:30
A13: 11 | B13: 12:55 13:24 | D13: Pe 2JD
A14: 12 | B14: 12:55 13:25 | D14: Pe 2JD
A15: 13 | B15: 13:25 13:55
A16: 14 | B16: 13:55 14:25

Sheet LW
A1: LW | B1: Time | C1: Monday | D1: Tuesday | E1: Wednesday | F1: Thursday | G1: Friday
B2: 07:55 08:00 | C2: Register Class
A3: 1 | B3: 08:00 08:30 | F3: Xhosa 5SN
A4: 2 | B4: 08:30 09:00 | F4: Xhosa 5SN
A5: 3 | B5: 09:00 09:30 | F5: Xhosa 5ER | G5: Xhosa 4WP
A6: 4 | B6: 09:30 10:00 | F6: Xhosa 5ER | G6: Xhosa 4WP
A7: 5 | B7: 10:00 10:25
A8: 6 | B8: 10:25 10:50 | D8: Xhosa 4WP | G8: History 5ER
A9: 7 | B9: 10:50 11:15 | C9: Afrik 5ER | D9: Xhosa 4WP
A10: 8 | B10: 11:15 11: 40 | C10: Afrik 5ER | E10: Xhosa 5ER
A11: 9 | B11: 11:40 12:05 | C11: Xhosa 5SN | D11: Afrik 5ER | E11: Xhosa 5ER | F11: Afrik 5ER | G11: History 5SN
A12: 10 | B12: 12:05 12:30 | C12: Xhosa 5SN | D12: Afrik 5ER | F12: Afrik 5ER | G12: History 5SN
A13: 11 | B13: 12:55 13:24
A14: 12 | B14: 12:55 13:25 | C14: Xhosa 5ER | F14: History 5SN
A15: 13 | B15: 13:25 13:55 | C15: Xhosa 5ER | D15: Xhosa 5SN | E15: History 5ER | F15: Xhosa 4WP
A16: 14 | B16: 13:55 14:25 | C16: Afrik 5ER | D16: Xhosa 5SN | E16: History 5ER | F16: Xhosa 4WP

Sheet SM
A1: SM | B1: Time | C1: Monday | D1: Tuesday | E1: Wednesday | F1: Thursday | G1: Friday
B2: 07:55 08:00 | C2: Register Class
A3: 1 | B3: 08:00 08:30
A4: 2 | B4: 08:30 09:00
A5: 3 | B5: 09:00 09:30
A6: 4 | B6: 09:30 10:00
A7: 5 | B7: 10:00 10:25
A8: 6 | B8: 10:25 10:50 | C8: Assembly 5SN | E8: Philosophy 7CC
A9: 7 | B9: 10:50 11:15 | C9: Philosophy 7CW | E9: Philosophy 7CC
A10: 8 | B10: 11:15 11: 40 | C10: Philosophy 7CW
A11: 9 | B11: 11:40 12:05 | E11: Chapel 3SJ
A12: 10 | B12: 12:05 12:30 | E12: Chapel 5SN
A13: 11 | B13: 12:30 12:55
A14: 12 | B14: 12:55 13:25
A15: 13 | B15: 13:25 13:55
A16: 14 | B16: 13:55 14:25

Sheet CHM
A1: CHM | B1: Time | C1: Monday | D1: Tuesday | E1: Wednesday | F1: Thursday | G1: Friday
B2: 07:55 08:00 | C2: Register Class
A3: 1 | B3: 08:00 08:30
A4: 2 | B4: 08:30 09:00
A5: 3 | B5: 09:00 09:30 | E5: Philosophy 5ER
A6: 4 | B6: 09:30 10:00 | E6: Philosophy 5ER
A7: 5 | B7: 10:00 10:25
A8: 6 | B8: 10:25 10:50
A9: 7 | B9: 10:50 11:15
A10: 8 | B10: 11:15 11: 40
A11: 9 | B11: 11:40 12:05
A12: 10 | B12: 12:05 12:30
A13: 11 | B13: 12:30 12:55
A14: 12 | B14: 12:55 13:25
A15: 13 | B15: 13:25 13:55 | F15: Philosophy 5SN
A16: 14 | B16: 13:55 14:25 | F16: Philosophy 5SN

Sheet FA
A1: RLW | B1: Time | C1: Monday | D1: Tuesday | E1: Wednesday | F1: Thursday | G1: Friday
B2: 07:55 08:00 | C2: Line up and lead in
A3: 1 | B3: 08:00 08:30
A4: 2 | B4: 08:30 09:00
A5: 3 | B5: 09:00 09:30
A6: 4 | B6: 09:30 10:00 | C6: 1st Break | D6: 1st Break | E6: 1st Break | F6: 1st Break
A7: 5 | B7: 10:00 10:25 | C7: Assembly | G7: Break
A8: 6 | B8: 10:25 10:50 | F8: Sure
A9: 7 | B9: 10:50 11:15
A10: 8 | B10: 11:15 11: 40
A11: 9 | B11: 11:40 12:05
A12: 10 | B12: 12:05 12:30 | C12: 2nd Break | D12: 2nd Break | E12: 2nd Break | F12: 2nd Break
A13: 11 | B13: 12:30 12:55
A14: 12 | B14: 12:55 13:30

Sheet PE
A1: PE | B1: Time | C1: Monday | D1: Tuesday | E1: Wednesday | F1: Thursday | G1: Friday
B2: 07:55 08:00 | C2: Register Class
A3: 1 | B3: 08:00 08:30
A4: 2 | B4: 08:30 09:00
A5: 3 | B5: 09:00 09:30 | F5: Pe IPLC
A6: 4 | B6: 09:30 10:00 | F6: Pe IPLC
A7: 5 | B7: 10:00 10:25
A8: 6 | B8: 10:25 10:50 | D8: Pe 5ER | F8: Pe RLW
A9: 7 | B9: 10:50 11:15 | C9: Pe 4WP | D9: Pe 5ER | F9: Pe RLW | G9: Pe 1MJ
A10: 8 | B10: 11:15 11: 40 | C10: Pe 4WP | G10: Pe 1MJ
A11: 9 | B11: 11:40 12:05 | G11: Pe 6CC
A12: 10 | B12: 12:05 12:30 | G12: Pe 6CC
A13: 11 | B13: 12:30 12:55 | C13: Pe OLC | D13: Pe 2JD | F13: Pe 3SJ
A14: 12 | B14: 12:55 13:25 | C14: Pe OLC | D14: Pe 2JD | F14: Pe 3SJ
A15: 13 | B15: 13:25 13:55 | F15: Pe 7CW
A16: 14 | B16: 13:55 14:25 | F16: Pe 7CW

Sheet Art
A1: Art | B1: Time | C1: Monday | D1: Tuesday | E1: Wednesday | F1: Thursday | G1: Friday
B2: 07:55 08:00 | C2: Register Class
A3: 1 | B3: 08:00 08:30 | D3: Maths 7CC | F3: Maths 7CC | G3: Art 5SN
A4: 2 | B4: 08:30 09:00 | D4: Maths 7CC | F4: Maths 7CC | G4: Art 5SN
A5: 3 | B5: 09:00 09:30 | C5: Maths 7CC | D5: Art 5ER | E5: Art 4WP | G5: Art OLC
A6: 4 | B6: 09:30 10:00 | C6: Maths 7CC | D6: Art 5ER | E6: Art 4WP | G6: Art OLC
A7: 5 | B7: 10:00 10:25 | E7: Art 3SJ
A8: 6 | B8: 10:25 10:50 | C8: Assembly 7CC | D8: Art IPLC | E8: Art 3SJ | F8: Sure/m 7CC
A9: 7 | B9: 10:50 11:15 | C9: Art 1AZ | D9: Art IPLC | F9: Art 2JD
A10: 8 | B10: 11:15 11: 40 | C10: Art 1AZ | E10: Art RLW | F10: Art 2JD | G10: Maths 7CC
A11: 9 | B11: 11:40 12:05 | D11: Art 7CW | E11: Art RLW | F11: Art 6CC | G11: Maths 7CC
A12: 10 | B12: 12:05 12:30 | D12: Art 7CW | E12: Chapel 7CC | F12: Art 6CC | G12: Maths 7CC
A13: 11 | B13: 12:30 12:55 | D13: Art 1MJ
A14: 12 | B14: 12:55 13:25 | C14: Art 3TA | D14: Art 1MJ | F14: Art 6RE
A15: 13 | B15: 13:25 13:55 | C15: Art 3TA | E15: Art 7CC | F15: Art 6RE
A16: 14 | B16: 13:55 14:25 | E16: Art 7CC

Sheet Music
A1: Music | B1: Time | C1: Monday | D1: Tuesday | E1: Wednesday | F1: Thursday | G1: Friday
B2: 07:55 08:00 | C2: Register Class
A3: 1 | B3: 08:00 08:30 | D3: Music 5SN | G3: Music 5ER
A4: 2 | B4: 08:30 09:00 | D4: Music 5SN | G4: Music 5ER
A5: 3 | B5: 09:00 09:30 | C5: Music IPLC | G5: Music 3TA
A6: 4 | B6: 09:30 10:00 | C6: Music IPLC | G6: Music 3TA
A7: 5 | B7: 10:00 10:25 | E7: Music 1MJ
A8: 6 | B8: 10:25 10:50 | C8: Assembly 7CC | D8: Choir 1AZ | E8: Music 1MJ
A9: 7 | B9: 10:50 11:15 | C9: Music OLC | D9: Choir 1AZ | F9: Music 7CC | G9: Music 4WP
A10: 8 | B10: 11:15 11: 40 | C10: Music OLC | D10: Music RLW | E10: Music 6CC | F10: Music 7CC | G10: Music 4WP
A11: 9 | B11: 11:40 12:05 | C11: Music 7CW | E11: Music 6CC | F11: Music 6RE | G11: Music 3SJ
A12: 10 | B12: 12:05 12:30 | C12: Music 7CW | F12: Music 6RE | G12: Music 3SJ
A13: 11 | B13: 12:30 12:55 | E13: Music 2JD
A14: 12 | B14: 12:55 13:25 | D14: Choir 4WP | E14: Music 2JD
A15: 13 | B15: 13:25 13:55
A16: 14 | B16: 13:55 14:25

Sheet Comp
A1: Comp | B1: Time | C1: Monday | D1: Tuesday | E1: Wednesday | F1: Thursday | G1: Friday
B2: 07:55 08:00 | C2: Register Class
A3: 1 | B3: 08:00 08:30 | C3: Ems 7CC | E3: Ems 7CW
A4: 2 | B4: 08:30 09:00 | C4: Ems 7CC | E4: Ems 7CW
A5: 3 | B5: 09:00 09:30 | D5: Comp IPLC | E5: Code/r 6RE | F5: Code/r 6CC
A6: 4 | B6: 09:30 10:00 | D6: Comp IPLC | E6: Code/r 6RE | F6: Code/r 6CC
A7: 5 | B7: 10:00 10:25 | F7: Comp 1MJ
A8: 6 | B8: 10:25 10:50 | C8: Comp RLW | D8: Code/r 6CC | E8: Code/r 6RE | G8: Comp 3TA
A9: 7 | B9: 10:50 11:15 | D9: Code/r 6CC | E9: Code/r 6RE | F9: Comp 1AZ | G9: Comp 3TA
A10: 8 | B10: 11:15 11: 40 | C10: Comp 2JD | E10: Comp 7CC
A11: 9 | B11: 11:40 12:05 | D11: Comp 4WP | E11: Comp 7CC | F11: Comp 7CW | G11: Comp 5ER
A12: 10 | B12: 12:05 12:30 | D12: Comp 4WP | F12: Comp 7CW | G12: Comp 5ER
A13: 11 | B13: 12:30 12:55 | C13: Comp 3SJ | E13: Comp OLC
A14: 12 | B14: 12:55 13:25 | C14: Comp 3SJ
A15: 13 | B15: 13:25 13:55 | C15: Comp 5SN
A16: 14 | B16: 13:55 14:25 | C16: Comp 5SN

Sheet Library
A1: Lib | B1: Time | C1: Monday | D1: Tuesday | E1: Wednesday | F1: Thursday | G1: Friday
B2: 07:55 08:00 | C2: Register Class
A3: 1 | B3: 08:00 08:30
A4: 2 | B4: 08:30 09:00
A5: 3 | B5: 09:00 09:30
A6: 4 | B6: 09:30 10:00
A7: 5 | B7: 10:00 10:25
A8: 6 | B8: 10:25 10:50 | D8: Library 6CC
A9: 7 | B9: 10:50 11:15 | C9: Library 1MJ | D9: Library RLW | G9: Library 2JD
A10: 8 | B10: 11:15 11: 40 | D10: Library 5ER
A11: 9 | B11: 11:40 12:05 | C11: Library 1AZ | G11: Library OLC
A12: 10 | B12: 12:05 12:30 | G12: Library IPLC
A13: 11 | B13: 12:30 12:55 | E13: Library 3SJ
A14: 12 | B14: 12:55 13:25 | C14: Library 5SN | E14: Library 4WP
A15: 13 | B15: 13:25 13:55 | C15: Library 6RE | E15: Library 3TA
A16: 14 | B16: 13:55 14:25 | C16: Library 7CC | E16: Library 7CW

Sheet Smuts
A1: Smuts | B1: Time | C1: Monday | D1: Tuesday | E1: Wednesday | F1: Thursday | G1: Friday
B2: 07:55 08:00 | C2: Register Class
A3: 1 | B3: 08:00 08:30 | D3: Maths 7CC | F3: Maths 7CC
A4: 2 | B4: 08:30 09:00 | D4: Maths 7CC | F4: Maths 7CC
A5: 3 | B5: 09:00 09:30 | C5: Maths 7CC
A6: 4 | B6: 09:30 10:00 | C6: Maths 7CC
A7: 5 | B7: 10:00 10:25
A8: 6 | B8: 10:25 10:50 | E8: Philosophy 7CC
A9: 7 | B9: 10:50 11:15 | C9: Philosophy 7CW | E9: Philosophy 7CC
A10: 8 | B10: 11:15 11: 40 | C10: Philosophy 7CW | G10: Maths 7CC
A11: 9 | B11: 11:40 12:05 | G11: Maths 7CC
A12: 10 | B12: 12:05 12:30 | G12: Maths 7CC
A13: 11 | B13: 12:30 12:55
A14: 12 | B14: 12:55 13:25
A15: 13 | B15: 13:25 13:55
A16: 14 | B16: 13:55 14:25

Sheet Subj
A1: #ERROR!
A2: Grade 3 | B2: Grade 4 | C2: Grade 5 | D2: Grade 6 | E2: Grade 7 | F2: Classes | H2: Pre Primary
A4: Art | B4: Art | C4: Art | D4: Art | E4: Art | F4: 7H | H4: Story
A5: Comp | B5: Comp | C5: Comp | D5: Comp | E5: Comp | F5: 7R | H5: OT
A6: Library | B6: Library | C6: Library | D6: Library | E6: Library | F6: 7LR | H6: Library
A7: Music | B7: Music | C7: Music | D7: Music | E7: Music | F7: 6G | H7: Art
A8: Xhosa | B8: Xhosa | C8: Xhosa | D8: Afrik/Xhosa | E8: Philosophy | F8: 6G | H8: Physio
A9: PE | B9: Philosophy | C9: Philosophy | D9: Philosophy | E9: PE | F9: 6W | H9: Salt
A10: Afrikaans | B10: PE | C10: PE | D10: PE | E10: Maths | F10: 5SF | H10: Playball
A11: Maths | B11: Maths | C11: Maths | D11: Maths | E11: Afrik/Xhosa | F11: 5O | H11: Afrikaans
A12: English | B12: Afrik | C12: Afrik | D12: Afrik | E12: Eng | F12: 5G | H12: Music
A13: Life SkilPhilosophy | B13: Eng | C13: Eng | D13: Eng | E13: EMS | F13: 4L | H13: Xhosa
A14: Chapel | B14: NS | C14: NS | D14: NST | E14: NST | F14: 4S | H14: Comp
... A17: Sure | B17: Chapel | C17: Chapel | D17: Chapel | E17: Chapel | F17: 3CS | H17: Judo
B18: Assembly | C18: Assembly | D18: Assembly | E18: Assembly | F18: 3K
B19: Choir | C19: Choir | D19: Choir | E19: Choir
B20: Sure/M | C20: Sure/M | D20: Sure/M | E20: Sure/M
D21: Code/R | E21: Code/R

Sheet Setup
A1: ClassName | B1: ClassTeacher | C1: Itinerant
A2: 7CC | B2: CC | C2: CC
A3: 7CW | B3: CW | C3: CW
A4: 6RE | B4: RE | C4: RE
A5: 6CC | B5: CC6 | C5: CC6
A6: 5SN | B6: SN | C6: SN
A7: 5ER | B7: ER | C7: ER
A8: 4WP | B8: WP | C8: WP
A9: 3TA | B9: TA | C9: Art
A10: 3SJ | B10: SJ | C10: Music
A11: 2JD | B11: JD | C11: Comp
A12: 1AZ | B12: AZ | C12: Library
... A15: Busybees | B15: AZ | C15: LW
A16: OLC | C16: SM
A17: IPLC | C17: CHM
B18: TD | C18: PE
B19: ZM
B20: LW
B21: SM

Sheet TeacherSubjects
A1: Teacher | B1: Class | C1: Subject
A2: Art
A3: Art | B3: =Setup!$A$2 -> 7CC | C3: Art
A4: Art | B4: =Setup!$A$3 -> 7CW | C4: Art
A5: Art | B5: =Setup!$A$4 -> 6RE | C5: Art
A6: Art | B6: =Setup!$A$5 -> 6CC | C6: Art
A7: Art | B7: =Setup!$A$6 -> 5SN | C7: Art
A8: Art | B8: =Setup!$A$7 -> 5ER | C8: Art
A9: Art | B9: =Setup!$A$8 -> 4WP | C9: Art
A10: Art | B10: =#REF! -> #REF! | C10: Art
A11: Art | B11: =Setup!$A$9 -> 3TA | C11: Art
A12: Art | B12: =Setup!$A$10 -> 3SJ | C12: Art
A13: Art | B13: =Setup!$A$11 -> 2JD | C13: Art
A14: Art | B14: =Setup!$A$13 -> 1MJ | C14: Art
A15: Art | B15: =Setup!$A$12 -> 1AZ | C15: Art
A16: Art | B16: =Setup!$A$14 -> RLW | C16: Art
A17: Art | B17: IPLC | C17: Art
A18: Art | B18: OLC | C18: Art
A19: Art | B19: =Setup!$A$2 -> 7CC | C19: Maths
A20: Art | B20: =Setup!$A$2 -> 7CC | C20: Assembly
A21: Art | B21: =Setup!$A$2 -> 7CC | C21: Chapel
A22: Art | B22: =Setup!$A$2 -> 7CC | C22: Sure/M
A23: Music
A24: Music | B24: =Setup!$A$2 -> 7CC | C24: Music
A25: Music | B25: =Setup!$A$3 -> 7CW | C25: Music
A26: Music | B26: =Setup!$A$4 -> 6RE | C26: Music
A27: Music | B27: =Setup!$A$5 -> 6CC | C27: Music
A28: Music | B28: =Setup!$A$6 -> 5SN | C28: Music
A29: Music | B29: =Setup!$A$7 -> 5ER | C29: Music
A30: Music | B30: =Setup!$A$8 -> 4WP | C30: Music
A31: Music | B31: =#REF! -> #REF! | C31: Music
A32: Music | B32: =Setup!$A$8 -> 4WP | C32: Choir
A33: Music | B33: =Setup!$A$9 -> 3TA | C33: Music
A34: Music | B34: =Setup!$A$10 -> 3SJ | C34: Music
A35: Music | B35: =Setup!$A$11 -> 2JD | C35: Music
A36: Music | B36: =Setup!$A$13 -> 1MJ | C36: Music
A37: Music | B37: =Setup!$A$14 -> RLW | C37: Music
A38: Music | B38: =Setup!$A$12 -> 1AZ | C38: Choir
A39: Music | B39: =#REF! -> #REF! | C39: Music
A40: Music | B40: =Setup!$A$15 -> Busybees | C40: Music
...
